Workbook
Name Excel_BuiltIn_Print_Area: 'Cost price'!$A$1:$G$52
Name Excel_BuiltIn_Print_Area: Stages!$A$1:$W$21

Sheet Cost price
A1: Форелевое хозяйство 500 т
A5: Производительность | B5: 500000 | C5: kг/год
A6: Площадь производственного корпуса | B6: =500*B5/100000 -> 2500 | C6: m²
A7: Персонал | E7: Tax
B8: персонал | C8: зарплата | D8: всего | E8: Соц. Налог | F8: Риски
E9: 0.4 | F9: 0
A10: Директор-инженер | B10: 1 | C10: 3000 | D10: =C10*B10 -> 3000 | E10: =E$9*D10 -> 1200 | F10: =B10*F$9 -> 0
A11: Помощник директора | B11: 1 | C11: 1500 | D11: =C11*B11 -> 1500 | E11: =E$9*D11 -> 600 | F11: =B11*F$9 -> 0
A12: Секретарь | B12: 1 | C12: 800 | D12: =C12*B12 -> 800 | E12: =E$9*D12 -> 320 | F12: =B12*F$9 -> 0
A13: Бухгалтер | B13: 1 | C13: 800 | D13: =C13*B13 -> 800 | E13: =E$9*D13 -> 320 | F13: =B13*F$9 -> 0
A14: Рыбовод | B14: 1 | C14: 2000 | D14: =C14*B14 -> 2000 | E14: =E$9*D14 -> 800 | F14: =B14*F$9 -> 0
A15: Оператор | B15: 4 | C15: 950 | D15: =C15*B15 -> 3800 | E15: =E$9*D15 -> 1520 | F15: =B15*F$9 -> 0
A16: Инженер | B16: 1 | C16: 1500 | D16: =C16*B16 -> 1500 | E16: =E$9*D16 -> 600 | F16: =B16*F$9 -> 0
A17: Охранная фирма | B17: 1 | C17: 100 | D17: =C17*B17 -> 100 | E17: =E$9*D17 -> 40 | F17: =B17*F$9 -> 0
B18: =SUM(B10:B17) -> 11 | D18: =SUM(D10:D17) -> 13500 | E18: =SUM(E10:E17) -> 5400 | F18: =SUM(F10:F17) -> 0
A19: Всего: | D19: =(D18+E18+F18)*1.1 -> 20790 | E19: €
D20: буфер +10%
A21: Инвестиции
A22: Земля | B22: 170000
A23: Стоимость технологического проекта и консультационного сопровождения проекта | B23: 40000
A24: Разработка технического проекта и местные согласования | B24: 40000
A26: Оборудование | B26: 2500000
A27: Установка оборудования | B27: 105383
A28: Строительство | B28: 2200000
A29: Всего: | B29: =SUM(B22:B28) -> 5055383
A32: Production costs
A33: Статья расходов | B33: Кол-во | C33: ед. | D33: цена/ед. | E33: Затраты
E34: общий | F34: за 1 кг
A35: Вода | B35: =40*24*365*B5/100000 -> 1752000 | C35: m³/year | D35: =15/445*D38 -> 0.0043820225 | E35: =D35*B35 -> 7677.3034 | F35: =E35/$B$5 -> 0.015354607
A36: Корм (feed ratio 1.0) | B36: =B5*1.2 -> 600000 | C36: kg/year | D36: 1.6 | E36: =D36*B36 -> 960000 | F36: =E36/$B$5 -> 1.92
A37: Мальки | B37: =73000*B5/100000 -> 365000 | C37: 1/year | D37: 0.19 | E37: =D37*B37 -> 69350 | F37: =E37/$B$5 -> 0.1387
A38: Электричество | B38: =B5*2.6 -> 1300000 | C38: kWt/year | D38: 0.13 | E38: =D38*B38 -> 169000 | F38: =E38/$B$5 -> 0.338
A39: Кислород сжиженный | B39: =B5*0.45 -> 225000 | C39: kg/year | D39: 0.246 | E39: =D39*B39 -> 55350 | F39: =E39/$B$5 -> 0.1107
A40: Соль | B40: =1.5/1000000*B5*365 -> 273.75 | C40: T/year | D40: 170 | E40: =D40*B40 -> 46537.5 | F40: =E40/$B$5 -> 0.093075
A41: Сода | B41: =B36*0.25/1000 -> 150 | C41: T/year | D41: 500 | E41: =D41*B41 -> 75000 | F41: =E41/$B$5 -> 0.15
A42: Зарплата | B42: =B18 -> 11 | C42: people | D42: =D19/B42*12 -> 22680 | E42: =D42*B42 -> 249480 | F42: =E42/$B$5 -> 0.49896
A43: Обогрев (gas, efficiency = 95%) | B43: =0 -> 0 | C43: m³ | D43: 0.4 | E43: =D43*B43 -> 0 | F43: =E43/$B$5 -> 0
A44: Всего: | E44: =SUM(E35:E43) -> 1632394.8 | F44: =SUM(F35:F43) -> 3.2647896
A46: Другие расходы
A47: Здание | B47: Оценка | C47: ед. | D47: База | E47: общий | F47: за 1 кг
...

Sheet Cash Flow
C1: Cash Flow
A2: Основные данные
A3: Параметры
A4: Продолжительность проекта | B4: годы | C4: 10
A5: Цена капитала или инфляция | C5: 0.05 | E5: *
A6: Годовое производство | B6: тонн/год | C6: ='Cost price'!B5/1000 -> 500 | E6: *
A7: Средний приход | B7: €/Kg | C7: 5 | E7: *
A8: Общие инвестиции | B8: €*1000 | C8: ='Cost price'!B29/1000 -> 5055.383
A9: Евро фонды 60% дотация | B9: €*1000 | C9: 3000
A11: Вода | B11: €/Kg | C11: ='Cost price'!F35 -> 0.015354607
A12: Корм | B12: €/Kg | C12: ='Cost price'!F36 -> 1.92
A13: Мальки | B13: €/Kg | C13: ='Cost price'!F37 -> 0.1387
A14: Электричество | B14: €/Kg | C14: ='Cost price'!F38 -> 0.338
A15: Кислород сжиженный | B15: €/Kg | C15: ='Cost price'!F39 -> 0.1107
A16: Соль | B16: €/T | C16: ='Cost price'!F40 -> 0.093075
A17: Сода | B17: €/T | C17: ='Cost price'!F41 -> 0.15
A18: Зарплата персоналу | B18: €/Kg | C18: ='Cost price'!F42 -> 0.49896
A19: Обогрев | B19: €/Kg | C19: ='Cost price'!F43 -> 0
C20: =SUM(C11:C19) -> 3.2647896 | E20: Индексация затрат и цен реализации с учетом инфляции не производится.
A22: Cash Flow [€*1000]
B23: 0 | C23: 1 | D23: 2 | E23: 3 | F23: 4 | G23: 5 | H23: 6 | I23: 7 | J23: 8 | K23: 9 | L23: 10 | M23: 11 | N23: 12 | O23: 13 | P23: 14 | Q23: 15 | R23: 16 | S23: 17 | T23: 18 | U23: 19 | V23: 20
A24: Года | B24: 2026 | C24: =B24+1 -> 2027 | D24: =C24+1 -> 2028 | E24: =D24+1 -> 2029 | F24: =E24+1 -> 2030 | G24: =F24+1 -> 2031 | H24: =G24+1 -> 2032 | I24: =H24+1 -> 2033 | J24: =I24+1 -> 2034 | ... V24: =U24+1 -> 2046
A26: В год производство [т/год] | B26: =$C$6*(12-Stages!C41)/12 -> 0 | C26: 0 | D26: =$C$6 -> 500 | E26: =$C$6 -> 500 | F26: =$C$6 -> 500 | G26: =$C$6 -> 500 | H26: =$C$6 -> 500 | I26: =$C$6 -> 500 | J26: =$C$6 -> 500 | K26: =$C$6 -> 500 | ... V26: =$C$6 -> 500
A27: Приход от продажи [€/кг] | B27: =$C$7 -> 5 | C27: =$C$7 -> 5 | D27: =$C$7 -> 5 | E27: =$C$7 -> 5 | F27: =$C$7 -> 5 | G27: =$C$7 -> 5 | H27: =$C$7 -> 5 | I27: =$C$7 -> 5 | ... V27: =$C$7 -> 5
A28: Всего в год [€*1000/год] | B28: =B27*B26 -> 0 | C28: =C27*C26 -> 0 | D28: =D27*D26 -> 2500 | E28: =E27*E26 -> 2500 | F28: =F27*F26 -> 2500 | G28: =G27*G26 -> 2500 | H28: =H27*H26 -> 2500 | I28: =I27*I26 -> 2500 | ... V28: =V27*V26 -> 2500
A30: Всего инвестиций | B30: =-C8+C9 -> -2055.383
A32: Оборотные средства [€*1000/год]
A33: Вода | B33: =$C11*$C$6*SUM(Stages!H$24:S$24)/12*Stages!C38 -> 0.57579775 | C33: =$C11*$C$6*SUM(Stages!T24:AE24)/12 -> 7.6773034 | D33: =$C11*$C$6 -> 7.6773034 | E33: =$C11*$C$6 -> 7.6773034 | F33: =$C11*$C$6 -> 7.6773034 | G33: =$C11*$C$6 -> 7.6773034 | H33: =$C11*$C$6 -> 7.6773034 | I33: =$C11*$C$6 -> 7.6773034 | J33: =$C11*$C$6 -> 7.6773034 | K33: =$C11*$C$6 -> 7.6773034 | ... V33: =$C11*$C$6 -> 7.6773034
A34: Корм | B34: =$C12*$C$6*SUM(Stages!H25:S25)/12*Stages!C45*Stages!C38 -> 72 | C34: =$C12*$C$6*SUM(Stages!T25:AE25)/12*Stages!C45 -> 960 | D34: =$C12*$C$6 -> 960 | E34: =$C12*$C$6 -> 960 | F34: =$C12*$C$6 -> 960 | G34: =$C12*$C$6 -> 960 | H34: =$C12*$C$6 -> 960 | I34: =$C12*$C$6 -> 960 | J34: =$C12*$C$6 -> 960 | K34: =$C12*$C$6 -> 960 | ... V34: =$C12*$C$6 -> 960
A35: Мальки | B35: =$C13*$C$6*SUM(Stages!H26:S26)/12*Stages!C48 -> 69.35 | C35: =$C13*$C$6*SUM(Stages!T26:AE26)/12*Stages!C48 -> 69.35 | D35: =$C13*$C$6 -> 69.35 | E35: =$C13*$C$6 -> 69.35 | F35: =$C13*$C$6 -> 69.35 | G35: =$C13*$C$6 -> 69.35 | H35: =$C13*$C$6 -> 69.35 | I35: =$C13*$C$6 -> 69.35 | J35: =$C13*$C$6 -> 69.35 | K35: =$C13*$C$6 -> 69.35 | ... V35: =$C13*$C$6 -> 69.35
A36: Электричество | B36: =$C14*$C$6*SUM(Stages!H27:S27)/12*Stages!C38 -> 12.675 | C36: =$C14*$C$6*SUM(Stages!T26:AE26)/12 -> 14.083333 | D36: =$C14*$C$6 -> 169 | E36: =$C14*$C$6 -> 169 | F36: =$C14*$C$6 -> 169 | G36: =$C14*$C$6 -> 169 | H36: =$C14*$C$6 -> 169 | I36: =$C14*$C$6 -> 169 | J36: =$C14*$C$6 -> 169 | K36: =$C14*$C$6 -> 169 | ... V36: =$C14*$C$6 -> 169
A37: Кислород сжиженный | B37: =$C15*$C$6*SUM(Stages!H28:S28)/12*Stages!C38 -> 4.15125 | C37: =$C15*$C$6*SUM(Stages!T27:AE27)/12 -> 55.35 | D37: =$C15*$C$6 -> 55.35 | E37: =$C15*$C$6 -> 55.35 | F37: =$C15*$C$6 -> 55.35 | G37: =$C15*$C$6 -> 55.35 | H37: =$C15*$C$6 -> 55.35 | I37: =$C15*$C$6 -> 55.35 | J37: =$C15*$C$6 -> 55.35 | K37: =$C15*$C$6 -> 55.35 | ... V37: =$C15*$C$6 -> 55.35
A38: Соль | B38: =$C16*$C$6*SUM(Stages!H29:S29)/12*Stages!C38 -> 3.4903125 | C38: =$C16*$C$6*SUM(Stages!T28:AE28)/12 -> 46.5375 | D38: =$C16*$C$6 -> 46.5375 | E38: =$C16*$C$6 -> 46.5375 | F38: =$C16*$C$6 -> 46.5375 | G38: =$C16*$C$6 -> 46.5375 | H38: =$C16*$C$6 -> 46.5375 | I38: =$C16*$C$6 -> 46.5375 | J38: =$C16*$C$6 -> 46.5375 | K38: =$C16*$C$6 -> 46.5375 | ... V38: =$C16*$C$6 -> 46.5375
A39: Сода | B39: =$C17*$C$6*SUM(Stages!H30:S30)/12*Stages!C38 -> 5.625 | C39: =$C17*$C$6*SUM(Stages!T29:AE29)/12 -> 75 | D39: =$C17*$C$6 -> 75 | E39: =$C17*$C$6 -> 75 | F39: =$C17*$C$6 -> 75 | G39: =$C17*$C$6 -> 75 | H39: =$C17*$C$6 -> 75 | I39: =$C17*$C$6 -> 75 | J39: =$C17*$C$6 -> 75 | K39: =$C17*$C$6 -> 75 | ... V39: =$C17*$C$6 -> 75
A40: Зарплата | B40: =$C18*$C$6*SUM(Stages!H31:S31)/12*Stages!C38 -> 18.711 | C40: =$C18*$C$6*SUM(Stages!T31:AE31)/12 -> 249.48 | D40: =$C18*$C$6 -> 249.48 | E40: =$C18*$C$6 -> 249.48 | F40: =$C18*$C$6 -> 249.48 | G40: =$C18*$C$6 -> 249.48 | H40: =$C18*$C$6 -> 249.48 | I40: =$C18*$C$6 -> 249.48 | J40: =$C18*$C$6 -> 249.48 | K40: =$C18*$C$6 -> 249.48 | ... V40: =$C18*$C$6 -> 249.48
A41: Обогрев | B41: =$C19*$C$6*SUM(Stages!H32:S32)/12*Stages!C38 -> 0 | C41: =$C19*$C$6*SUM(Stages!T32:AE32)/12 -> 0 | D41: =$C19*$C$6 -> 0 | E41: =$C19*$C$6 -> 0 | F41: =$C19*$C$6 -> 0 | G41: =$C19*$C$6 -> 0 | H41: =$C19*$C$6 -> 0 | I41: =$C19*$C$6 -> 0 | J41: =$C19*$C$6 -> 0 | K41: =$C19*$C$6 -> 0 | ... V41: =$C19*$C$6 -> 0
A43: Другие расходы | B43: 0 | C43: ='Cost price'!E50/1000 -> 154 | D43: =C43 -> 154 | E43: =D43 -> 154 | F43: =E43 -> 154 | G43: =F43 -> 154 | H43: =G43 -> 154 | I43: =H43 -> 154 | J43: =I43 -> 154 | K43: =J43 -> 154 | ... V43: =U43 -> 154
A44: Всего оборотных средств | B44: =SUM(B33:B43) -> 186.57836 | C44: =SUM(C33:C43) -> 1631.4781 | D44: =SUM(D33:D43) -> 1786.3948 | E44: =SUM(E33:E43) -> 1786.3948 | F44: =SUM(F33:F43) -> 1786.3948 | G44: =SUM(G33:G43) -> 1786.3948 | H44: =SUM(H33:H43) -> 1786.3948 | I44: =SUM(I33:I43) -> 1786.3948 | ... V44: =SUM(V33:V43) -> 1786.3948
A46: Кэш фло, без налогов | B46: =-B44+B30+B28 -> -2241.9614 | C46: =-C44+C30+C28 -> -1631.4781 | D46: =-D44+D30+D28 -> 713.6052 | E46: =-E44+E30+E28 -> 713.6052 | F46: =-F44+F30+F28 -> 713.6052 | G46: =-G44+G30+G28 -> 713.6052 | H46: =-H44+H30+H28 -> 713.6052 | I46: =-I44+I30+I28 -> 713.6052 | ... V46: =-V44+V30+V28 -> 713.6052
A47: Суммирование по годам | B47: =B46 -> -2241.9614 | C47: =B47+C46 -> -3873.4395 | D47: =C47+D46 -> -3159.8343 | E47: =D47+E46 -> -2446.2291 | F47: =E47+F46 -> -1732.6239 | G47: =F47+G46 -> -1019.0187 | H47: =G47+H46 -> -305.41351 | I47: =H47+I46 -> 408.19168 | J47: =I47+J46 -> 1121.7969 | ... V47: =U47+V46 -> 9685.0592
...

Sheet Stages
B2: Список этапов
A4: № | B4: Этап | C4: Дней | D4: Дата начала | E4: Дата окончания | F4: Стоимость | G4: Стоимость | H4: Месяцы 1-ого года | T4: Месяцы 2-ого года
F5: (EUR) | G5: (LV) | H5: 1 | I5: 2 | J5: 3 | K5: 4 | L5: 5 | M5: 6 | N5: 7 | O5: 8 | P5: 9 | Q5: 10 | R5: 11 | S5: 12 | T5: 1 | U5: 2 | V5: 3 | W5: 4 | X5: 5 | Y5: 6 | Z5: 7 | AA5: 8 | AB5: 9 | AC5: 10 | AD5: 11 | AE5: 12
A6: 1. | B6: Проектирование УЗВ | C6: =4*30 -> 120 | F6: =F7+F8+F9 -> 80000
A7: 1.1. | B7: Подготовка технологического проекта и консультативное сопровождение проекта | F7: ='Cost price'!B23 -> 40000
A8: 1.2. | B8: Разработка и местное согласование эскизного проекта | F8: ='Cost price'!B24*(1-0.9) -> 4000
A9: 1.2. | B9: Подготовка и местное согласование технического проекта | F9: ='Cost price'!B24-Stages!F8 -> 36000
A10: 2. | B10: Строительство здания | C10: =5*30 -> 150 | F10: ='Cost price'!B28 -> 2200000
A11: 2.1. | B11: Подготовка площадки
A12: 2.2. | B12: Фундамент
A13: 2.3. | B13: Здание
A14: 2.4. | B14: Внутренняя отделка
A15: 2.5. | B15: Подключение к внешним инженерным сетям
A16: 3. | B16: Покупка оборудования и монтаж | C16: =3*30 -> 90 | F16: =F17+F18 -> 2710766
A17: 3.1. | B17: Покупка оборудования и монтаж | F17: ='Cost price'!B26+'Cost price'!B27 -> 2605383
A18: 3.2. | B18: Монтаж | F18: ='Cost price'!B27 -> 105383
A19: 4. | B19: Запуск УЗВ | C19: =1*30 -> 30
A20: 5. | B20: Реализация рыбы
B22: Платежи
H23: 1 | I23: 2 | J23: 3 | K23: 4 | L23: 5 | M23: 6 | N23: 7 | O23: 8 | P23: 9 | Q23: 10 | R23: 11 | S23: 12 | T23: 1 | U23: 2 | V23: 3 | W23: 4 | X23: 5 | Y23: 6 | Z23: 7 | AA23: 8 | AB23: 9 | AC23: 10 | AD23: 11 | AE23: 12
A24: 1. | B24: ='Cost price'!A35 -> Вода | H24: 0 | I24: 0 | J24: 0 | K24: 0 | L24: 0 | M24: 0 | N24: 0 | O24: 0 | P24: 0 | Q24: 1 | R24: 1 | S24: 1 | T24: 1 | U24: 1 | V24: 1 | W24: 1 | X24: 1 | Y24: 1 | Z24: 1 | AA24: 1 | AB24: 1 | AC24: 1 | AD24: 1 | AE24: 1
A25: 2. | B25: ='Cost price'!A36 -> Корм (feed ratio 1.0) | H25: 0 | I25: 0 | J25: 0 | K25: 0 | L25: 0 | M25: 0 | N25: 0 | O25: 0 | P25: 0 | Q25: 1 | R25: 0 | S25: 0 | T25: 1 | U25: 0 | V25: 0 | W25: 1 | X25: 0 | Y25: 0 | Z25: 1 | AA25: 0 | AB25: 0 | AC25: 1 | AD25: 0 | AE25: 0
A26: 3. | B26: ='Cost price'!A37 -> Мальки | H26: 0 | I26: 0 | J26: 0 | K26: 0 | L26: 0 | M26: 0 | N26: 0 | O26: 0 | P26: 0 | Q26: 1 | R26: 0 | S26: 0 | T26: 0 | U26: 0 | V26: 0 | W26: 0 | X26: 0 | Y26: 0 | Z26: 0 | AA26: 0 | AB26: 0 | AC26: 1 | AD26: 0 | AE26: 0
A27: 7. | B27: ='Cost price'!A38 -> Электричество | H27: 0 | I27: 0 | J27: 0 | K27: 0 | L27: 0 | M27: 0 | N27: 0 | O27: 0 | P27: 0 | Q27: 1 | R27: 1 | S27: 1 | T27: 1 | U27: 1 | V27: 1 | W27: 1 | X27: 1 | Y27: 1 | Z27: 1 | AA27: 1 | AB27: 1 | AC27: 1 | AD27: 1 | AE27: 1
A28: 4. | B28: Кислород Сжиженный | H28: 0 | I28: 0 | J28: 0 | K28: 0 | L28: 0 | M28: 0 | N28: 0 | O28: 0 | P28: 0 | Q28: 1 | R28: 1 | S28: 1 | T28: 1 | U28: 1 | V28: 1 | W28: 1 | X28: 1 | Y28: 1 | Z28: 1 | AA28: 1 | AB28: 1 | AC28: 1 | AD28: 1 | AE28: 1
A29: 5. | B29: Соль | H29: 0 | I29: 0 | J29: 0 | K29: 0 | L29: 0 | M29: 0 | N29: 0 | O29: 0 | P29: 0 | Q29: 1 | R29: 1 | S29: 1 | T29: 1 | U29: 1 | V29: 1 | W29: 1 | X29: 1 | Y29: 1 | Z29: 1 | AA29: 1 | AB29: 1 | AC29: 1 | AD29: 1 | AE29: 1
A30: 6. | B30: Сода | H30: 0 | I30: 0 | J30: 0 | K30: 0 | L30: 0 | M30: 0 | N30: 0 | O30: 0 | P30: 0 | Q30: 1 | R30: 1 | S30: 1 | T30: 1 | U30: 1 | V30: 1 | W30: 1 | X30: 1 | Y30: 1 | Z30: 1 | AA30: 1 | AB30: 1 | AC30: 1 | AD30: 1 | AE30: 1
A31: 8. | B31: ='Cost price'!A42 -> Зарплата | H31: 0 | I31: 0 | J31: 0 | K31: 0 | L31: 0 | M31: 0 | N31: 0 | O31: 0 | P31: 0 | Q31: 1 | R31: 1 | S31: 1 | T31: 1 | U31: 1 | V31: 1 | W31: 1 | X31: 1 | Y31: 1 | Z31: 1 | AA31: 1 | AB31: 1 | AC31: 1 | AD31: 1 | AE31: 1
A32: 9. | B32: ='Cost price'!A43 -> Обогрев (gas, efficiency = 95%) | H32: 0 | I32: 0 | J32: 0 | K32: 0 | L32: 0 | M32: 0 | N32: 0 | O32: 0 | P32: 0 | Q32: 1 | R32: 1 | S32: 1 | T32: 1 | U32: 1 | V32: 1 | W32: 1 | X32: 1 | Y32: 1 | Z32: 1 | AA32: 1 | AB32: 1 | AC32: 1 | AD32: 1 | AE32: 1
B35: Время работы УЗВ
B36: В первом году работаем | C36: 3 | D36: месяца
B37: Во втором году работаем | C37: 12 | D37: месяцев
B38: В первом году затраты меньше | C38: 0.3
B40: Урожай когда
B41: В перво году начинаем получать рыбу | C41: 12 | D41: месяцев | E41: Если 12 месяц, значит не получаем рыбу в этом году.
B42: Во втором годе начинаем получать рыбу | C42: 10 | D42: месяц
B44: Корм
B45: Поставки каждый | C45: 3 | D45: месяц
B47: Мальки
B48: Поставки каждый | C48: 12 | D48: месяцев
...

Sheet Разбивка
A2: Инвестиции
A4: Земля | B4: 200000
A5: Строительство | B5: 2942964.5
A6: Солнечные панели | B6: 264633.87
A7: Комплект оборудования для рыбной фермы | B7: 1887019
A8: Технический проект, строительный и авторский надзор | B8: 50000
A9: Технологический проект и авторский надзор | B9: 50000
A10: Установка оборудования | B10: 100000
A11: Общая сумма инвестиций в основные средства | B11: =SUM(B4:B10) -> 5494617.4
